Workbook

Sheet Read Me
A1: Retail Footprint Expansion Model
A2: All sales, retailer and store data in this workbook is SIMULATED. It is not real company data and exists only to explain the method. District boundaries (geoBoundaries) and population (Pakistan Population Census 2023) are public.
A4: What this model answers | B4: How many new freezers should the business invest in, in each district, and do enough real shops exist to take them?
A5: Who it is for | B5: Anyone in Sales, Finance, Marketing or Operations. No coding needed: change the blue cells on the Inputs sheet and everything recalculates.
A6: How to use it | B6: 1. Review or change the settings on the Inputs sheet. 2. Read the results on the Model and Summary sheets. 3. Optional: run the macro RunFootprintModel (see vba/FootprintModel.bas) to recalculate outlet recommendations step by step on the Macro Results sheet.
A7: Color code | B7: Blue text on yellow = input you can change. Black text = formula. Green text = link to another sheet.
A9: Glossary
A10: PCC | B10: Per Capita Consumption: liters of ice cream sold per target person per year (Volume / Target population).
A11: PPO | B11: Population Per Outlet: target people for every freezer outlet (Target population / Outlets). High PPO means underserved.
A12: TP | B12: Throughput: liters sold per freezer per week (Volume / Outlets / Weeks). One outlet means one freezer.
A13: NI | B13: New Induction: a retailer that received a freezer during the year. NI TP is the throughput of those new retailers.
A14: LSM 5+ | B14: Living Standards Measure 5 and above: the share of people who can afford to buy ice cream regularly (the target population).
A15: GOLY | B15: Growth Over Last Year.
A16: CAGR | B16: Compound Annual Growth Rate (2022 to 2024).
A17: Ideal TP / Ideal PPO | B17: Benchmarks. Freezers are added until TP falls to the Ideal TP or PPO falls to the Ideal PPO, whichever comes first.
A18: First fill | B18: Liters needed to stock a brand new freezer the first time.
A19: Census universe | B19: Stores from a third party retail census that sell the main snacking competitors, are in a target channel, have high turnover and are not already customers.
A20: Conversion rate | B20: Share of census universe stores expected to agree to take a freezer.
A21: Expansion wave | B21: Order of expansion from the strategy: 1 Strongholds (citadel and distributor based districts), 2 their Neighbouring districts, 3 Population High districts, 4 the Rest.

Sheet Inputs
A1: Inputs (edit the blue cells)
A2: All sales, retailer and store data in this workbook is SIMULATED. It is not real company data and exists only to explain the method. District boundaries (geoBoundaries) and population (Pakistan Population Census 2023) are public.
A4: Setting | B4: Value | C4: Note
A5: Ideal TP (liters per freezer per week) | B5: 15 | C5: Stop adding freezers when throughput falls to this level.
A6: Ideal PPO (target people per outlet) | B6: 750 | C6: Industry benchmark.
A7: Weeks per year | B7: 52 | C7: Volumes are full year volumes.
A8: First fill per new freezer (liters) | B8: 80 | C8: Stock needed the first time a freezer is placed.
A9: Throughput assumed for each new outlet | B9: NI TP | C9: NI TP = throughput of last year's new retailers (original method). District TP = average of all retailers.
A10: Census conversion rate | B10: 0.8 | C10: Share of eligible census stores expected to accept a freezer.
A11: Number of districts in the shortlist | B11: 50 | C11: Top districts by priority.
A12: Budget scenario 1 (freezers funded) | B12: 4000 | C12: Shared across shortlisted districts by contribution.
A13: Budget scenario 2 (freezers funded) | B13: 6000 | C13: Shared across shortlisted districts by contribution.
A14: Rollout share in 2025 | B14: 0.35294118 | C14: Original plan split: 300, 300 and 250 out of 850.
A15: Rollout share in 2026 | B15: 0.35294118 | C15: Original plan split: 300, 300 and 250 out of 850.
A16: Rollout share in 2027 | B16: 0.29411765 | C16: Original plan split: 300, 300 and 250 out of 850.
A17: PCC threshold for Layer 01 | B17: 1.2 | C17: Liters per target person per year (at or above).
A18: PCC threshold for Layer 02 | B18: 0.8 | C18: Liters per target person per year (at or above).
A19: PCC threshold for Layer 03 | B19: 0.45 | C19: Liters per target person per year (at or above).
A20: PCC threshold for Layer 04 | B20: 0.2 | C20: Liters per target person per year (at or above).
A21: PPO threshold for Layer 01 | B21: 50000 | C21: Target people per outlet (at or above).
... A24: PPO threshold for Layer 04 | B24: 1700 | C24: Target people per outlet (at or above).
A26: Expansion wave by nature of district
A27: Stronghold | B27: 1
A28: Neighbouring | B28: 2
A29: Population High | B29: 3
A30: Rest | B30: 4

Sheet District Data
A1: District Data (inputs produced by the Python pipeline)
A2: All sales, retailer and store data in this workbook is SIMULATED. It is not real company data and exists only to explain the method. District boundaries (geoBoundaries) and population (Pakistan Population Census 2023) are public.
A4: District | B4: Province | C4: Sales region | D4: Nature of district | E4: Population 2024 (census based) | F4: LSM 5+ share | G4: Retailers 2022 | H4: Retailers 2023 | I4: Retailers 2024 | J4: Volume 2022 (liters) | K4: Volume 2023 (liters) | L4: Volume 2024 (liters) | M4: NI retailers 2024 | N4: NI volume 2024 (liters) | O4: Census universe stores (eligible, not yet customers)
A5: Abbottabad | B5: Khyber Pakhtunkhwa | C5: Islamabad Region | D5: Stronghold | E5: 1433930 | F5: 0.263 | G5: 73 | H5: 83 | I5: 92 | J5: 68046.3 | K5: 69542.7 | L5: 73950 | M5: 11 | N5: 3998.4 | O5: 31
A6: Attock | B6: Punjab | C6: Islamabad Region | D6: Stronghold | E6: 2221754 | F6: 0.26 | G6: 95 | H6: 102 | I6: 111 | J6: 90393.5 | K6: 93093.3 | L6: 96099.2 | M6: 16 | N6: 7956.8 | O6: 52
A7: Awaran | B7: Balochistan | C7: Karachi Region | D7: Rest | E7: 190805 | F7: 0.288 | G7: 4 | H7: 5 | I7: 6 | J7: 2925.9 | K7: 3270.7 | L7: 3475.4 | M7: 2 | N7: 597.1 | O7: 5
A8: Badin | B8: Sindh | C8: Karachi Region | D8: Neighbouring | E8: 1971828 | F8: 0.237 | G8: 90 | H8: 102 | I8: 110 | J8: 75712.6 | K8: 79376 | L8: 88179.1 | M8: 11 | N8: 3682.7 | O8: 62
A9: Bahawalnagar | B9: Punjab | C9: Multan Region | D9: Population High | E9: 3656391 | F9: 0.25 | G9: 125 | H9: 140 | I9: 146 | J9: 103225.7 | K9: 108639 | L9: 107197.5 | M9: 11 | N9: 4583.2 | O9: 59
A10: Bahawalpur | B10: Punjab | C10: Multan Region | D10: Neighbouring | E10: 4397187 | F10: 0.375 | G10: 278 | H10: 284 | I10: 309 | J10: 185061.4 | K10: 187443.6 | L10: 191928.8 | M10: 35 | N10: 11835.4 | O10: 92
A11: Bajaur | B11: Khyber Pakhtunkhwa | C11: Peshawar Region | D11: Rest | E11: 1324087 | F11: 0.116 | G11: 13 | H11: 13 | I11: 17 | J11: 11250.9 | K11: 11906 | L11: 15684.7 | M11: 5 | N11: 5191.2 | O11: 6
A12: Bannu | B12: Khyber Pakhtunkhwa | C12: Peshawar Region | D12: Rest | E12: 1384206 | F12: 0.112 | G12: 14 | H12: 15 | I12: 15 | J12: 10422.9 | K12: 10923.5 | L12: 9416.3 | M12: 1 | N12: 296.4 | O12: 13
A13: Barkhan | B13: Balochistan | C13: Multan Region | D13: Rest | E13: 217610 | F13: 0.102 | G13: 2 | H13: 2 | I13: 2 | J13: 1411.2 | K13: 1354.7 | L13: 1300.4 | M13: 0 | N13: 0 | O13: 2
A14: Battagram | B14: Khyber Pakhtunkhwa | C14: Islamabad Region | D14: Rest | E14: 568202 | F14: 0.139 | G14: 8 | H14: 9 | I14: 11 | J14: 5637.5 | K14: 5648.3 | L14: 6229.2 | M14: 2 | N14: 479.5 | O14: 3
A15: Bhakkar | B15: Punjab | C15: Multan Region | D15: Neighbouring | E15: 2014452 | F15: 0.21 | G15: 32 | H15: 37 | I15: 38 | J15: 30377.2 | K15: 33087.5 | L15: 33995.5 | M15: 4 | N15: 3140.7 | O15: 66
A16: Buner | B16: Khyber Pakhtunkhwa | C16: Peshawar Region | D16: Neighbouring | E16: 1038650 | F16: 0.08 | G16: 7 | H16: 7 | I16: 7 | J16: 5150.6 | K16: 4514.1 | L16: 4501.2 | M16: 0 | N16: 0 | O16: 6
... A119: Ziarat | B119: Balochistan | C119: Multan Region | D119: Rest | E119: 194942 | F119: 0.232 | G119: 3 | H119: 3 | I119: 3 | J119: 907.8 | K119: 855.5 | L119: 806.3 | M119: 0 | N119: 0 | O119: 0

Sheet Model
A1: Model (all formulas)
C2: National PCC | D2: =SUM(F5:F119)/SUM(D5:D119) -> 0.43123703 | E2: Shortlist final total | F2: =SUM(AK5:AK119) -> 6765
A4: District | B4: Sales region | C4: Nature of district | D4: Target population 2024 (LSM 5+) | E4: Outlets 2024 | F4: Volume 2024 (liters) | G4: TP 2024 (liters per freezer per week) | H4: NI TP 2024 | I4: Region NI TP (used when a district had no NI) | J4: TP assumed per new outlet | K4: PCC 2024 (liters per target person) | L4: PPO 2024 | M4: Volume GOLY | N4: Volume CAGR 2022 to 2024 | O4: Outlets GOLY | P4: PCC layer | Q4: PPO layer | R4: Outlets to add before PPO reaches ideal | S4: TP gap per new outlet (liters per year) | T4: Outlets to add before TP reaches ideal | U4: RECOMMENDED NEW OUTLETS (Phase 1 demand) | V4: Limiting factor | W4: New total volume (liters) | X4: New total outlets | Y4: New TP | Z4: New PPO | AA4: Quadrant (PCC against PPO) | AB4: Phase | AC4: Quadrant (TP against PPO) | AD4: Expansion wave | AE4: Sort score (helper) | AF4: Priority rank | AG4: Shortlisted | AH4: Usable census supply | AI4: FINAL NEW OUTLETS (smaller of demand and supply) | AJ4: Constraint | AK4: Final, shortlisted only | AL4: Budget 1: exact share (helper) | AM4: Budget 1: whole part (helper) | AN4: Budget 1: remainder (helper) | AO4: BUDGET SCENARIO 1 FREEZERS | AP4: Budget 2: exact share (helper) | AQ4: Budget 2: whole part (helper) | AR4: Budget 2: remainder (helper) | AS4: BUDGET SCENARIO 2 FREEZERS | AT4: 2025 exact (helper) | AU4: 2026 exact (helper) | AV4: 2027 exact (helper) | AW4: 2025 whole (helper) | AX4: 2026 whole (helper) | AY4: 2027 whole (helper) | AZ4: 2025 remainder (helper) | BA4: 2026 remainder (helper) | BB4: 2027 remainder (helper) | BC4: Left to place (helper) | BD4: ROLLOUT 2025 | BE4: ROLLOUT 2026 | BF4: ROLLOUT 2027
A5: ='District Data'!A5 -> Abbottabad | B5: ='District Data'!C5 -> Islamabad Region | C5: ='District Data'!D5 -> Stronghold | D5: =ROUND('District Data'!E5*'District Data'!F5,0) -> 377124 | E5: ='District Data'!I5 -> 92 | F5: ='District Data'!L5 -> 73950 | G5: =IFERROR(F5/(E5*Weeks),0) -> 15.457776 | H5: =IFERROR('District Data'!N5/('District Data'!M5*Weeks),0) -> 6.9902098 | I5: =IFERROR(SUMIFS('District Data'!$N$5:$N$119,'District Data'!$C$5:$C$119,B5)/(SUMIFS('District Data'!$M$5:$M$119,'District Data'!$C$5:$C$119,B5)*Weeks),0) -> 8.4031158 | J5: =IF(TPBasis="NI TP",IF(H5>0,H5,I5),G5) -> 6.9902098 | K5: =IFERROR(F5/D5,0) -> 0.19608935 | L5: =IFERROR(D5/E5,0) -> 4099.1739 | M5: =IFERROR('District Data'!L5/'District Data'!K5-1,0) -> 0.063375451 | N5: =IFERROR(('District Data'!L5/'District Data'!J5)^(1/2)-1,0) -> 0.042477839 | O5: =IFERROR('District Data'!I5/'District Data'!H5-1,0) -> 0.10843373 | P5: =IF(K5>=PCC_L1,"Layer 01",IF(K5>=PCC_L2,"Layer 02",IF(K5>=PCC_L3,"Layer 03",IF(K5>=PCC_L4,"Layer 04","Layer 05")))) -> Layer 05 | Q5: =IF(L5>=PPO_L1,"Layer 01",IF(L5>=PPO_L2,"Layer 02",IF(L5>=PPO_L3,"Layer 03",IF(L5>=PPO_L4,"Layer 04","Layer 05")))) -> Layer 03 | R5: =D5/IdealPPO-E5 -> 410.832 | S5: =IdealTP*Weeks-(Weeks*J5+FirstFill) -> 336.50909 | T5: =IF(S5>0,(F5-IdealTP*Weeks*E5)/S5,1000000000000) -> 6.5079965 | U5: =IF(E5<=0,0,IF(G5<=IdealTP,0,IF(L5<=IdealPPO,0,INT(MIN(T5,R5)+0.000000001)))) -> 6 | V5: =IF(E5<=0,"No current outlets",IF(G5<=IdealTP,"TP already at or below ideal",IF(L5<=IdealPPO,"PPO already at or below ideal",IF(T5<=R5,"Stopped by TP reaching ideal","Stopped by PPO reaching ideal")))) -> Stopped by TP reaching ideal | W5: =F5+U5*(Weeks*J5+FirstFill) -> 76610.945 | X5: =E5+U5 -> 98 | Y5: =IFERROR(W5/(X5*Weeks),0) -> 15.033545 | Z5: =IFERROR(D5/X5,0) -> 3848.2041 | AA5: =IF(AND(K5>=NationalPCC,L5>IdealPPO),"Q1: High PCC, High PPO",IF(K5>=NationalPCC,"Q2: High PCC, Low PPO",IF(L5>IdealPPO,"Q3: Low PCC, High PPO","Q4: Low PCC, Low PPO"))) -> Q3: Low PCC, High PPO | AB5: =IF(K5>=NationalPCC,IF(L5>IdealPPO,"Phase 1","Phase 2"),"Phase 3") -> Phase 3 | AC5: =IF(AND(G5>IdealTP,L5>IdealPPO),"High TP, High PPO",IF(G5>IdealTP,"High TP, Low PPO",IF(L5>IdealPPO,"Low TP, High PPO","Low TP, Low PPO"))) -> High TP, High PPO | AD5: =INDEX(WaveNumbers,MATCH(C5,WaveNames,0)) -> 1 | AE5: =IF(U5>0,AD5*10000000+VALUE(RIGHT(AB5,1))*1000000+(1000000-U5)+ROW()/1000000,"") -> 13999994 | AF5: =IF(U5>0,COUNTIFS($AE$5:$AE$119,"<"&AE5)+1,"") -> 20 | AG5: =IF(AF5="","No",IF(AF5<=TopN,"Yes","No")) -> Yes | AH5: =INT('District Data'!O5*ConvRate) -> 24 | AI5: =MIN(U5,AH5) -> 6 | AJ5: =IF(U5=0,"No expansion",IF(AH5<U5,"Supply constrained (not enough shops)","Demand constrained (enough shops)")) -> Demand constrained (enough shops) | AK5: =IF(AG5="Yes",AI5,0) -> 6 | AL5: =IF(AG5="Yes",IF(Budget1>=ShortlistFinal,AK5,AK5/ShortlistFinal*Budget1),0) -> 3.5476718 | AM5: =INT(AL5) -> 3 | AN5: =IF(AND(AG5="Yes",Budget1<ShortlistFinal),AL5-AM5,-1) -> 0.54767184 | AO5: =IF(AG5<>"Yes",0,IF(Budget1>=ShortlistFinal,AK5,AM5+IF(COUNTIFS($AN$5:$AN$119,">"&AN5)+COUNTIFS($AN$5:$AN$119,AN5,$AF$5:$AF$119,"<"&AF5)<Budget1-SUM($AM$5:$AM$119),1,0))) -> 4 | AP5: =IF(AG5="Yes",IF(Budget2>=ShortlistFinal,AK5,AK5/ShortlistFinal*Budget2),0) -> 5.3215078 | AQ5: =INT(AP5) -> 5 | AR5: =IF(AND(AG5="Yes",Budget2<ShortlistFinal),AP5-AQ5,-1) -> 0.32150776 | AS5: =IF(AG5<>"Yes",0,IF(Budget2>=ShortlistFinal,AK5,AQ5+IF(COUNTIFS($AR$5:$AR$119,">"&AR5)+COUNTIFS($AR$5:$AR$119,AR5,$AF$5:$AF$119,"<"&AF5)<Budget2-SUM($AQ$5:$AQ$119),1,0))) -> 5 | AT5: =AK5*Share2025 -> 2.1176471 | AU5: =AK5*Share2026 -> 2.1176471 | AV5: =AK5*Share2027 -> 1.7647059 | AW5: =INT(AT5) -> 2 | AX5: =INT(AU5) -> 2 | AY5: =INT(AV5) -> 1 | AZ5: =AT5-AW5 -> 0.11764706 | BA5: =AU5-AX5 -> 0.11764706 | BB5: =AV5-AY5 -> 0.76470588 | BC5: =AK5-AW5-AX5-AY5 -> 1 | BD5: =AW5+IF((BA5>AZ5)+(BB5>AZ5)<BC5,1,0) -> 2 | BE5: =AX5+IF((AZ5>BA5)+(BB5>BA5)+(AZ5=BA5)<BC5,1,0) -> 2 | BF5: =AY5+IF((AZ5>BB5)+(BA5>BB5)+(AZ5=BB5)+(BA5=BB5)<BC5,1,0) -> 2
A6: ='District Data'!A6 -> Attock | B6: ='District Data'!C6 -> Islamabad Region | C6: ='District Data'!D6 -> Stronghold | D6: =ROUND('District Data'!E6*'District Data'!F6,0) -> 577656 | E6: ='District Data'!I6 -> 111 | F6: ='District Data'!L6 -> 96099.2 | G6: =IFERROR(F6/(E6*Weeks),0) -> 16.649203 | H6: =IFERROR('District Data'!N6/('District Data'!M6*Weeks),0) -> 9.5634615 | I6: =IFERROR(SUMIFS('District Data'!$N$5:$N$119,'District Data'!$C$5:$C$119,B6)/(SUMIFS('District Data'!$M$5:$M$119,'District Data'!$C$5:$C$119,B6)*Weeks),0) -> 8.4031158 | J6: =IF(TPBasis="NI TP",IF(H6>0,H6,I6),G6) -> 9.5634615 | K6: =IFERROR(F6/D6,0) -> 0.1663606 | L6: =IFERROR(D6/E6,0) -> 5204.1081 | M6: =IFERROR('District Data'!L6/'District Data'!K6-1,0) -> 0.032289112 | N6: =IFERROR(('District Data'!L6/'District Data'!J6)^(1/2)-1,0) -> 0.031077441 | O6: =IFERROR('District Data'!I6/'District Data'!H6-1,0) -> 0.088235294 | P6: =IF(K6>=PCC_L1,"Layer 01",IF(K6>=PCC_L2,"Layer 02",IF(K6>=PCC_L3,"Layer 03",IF(K6>=PCC_L4,"Layer 04","Layer 05")))) -> Layer 05 | Q6: =IF(L6>=PPO_L1,"Layer 01",IF(L6>=PPO_L2,"Layer 02",IF(L6>=PPO_L3,"Layer 03",IF(L6>=PPO_L4,"Layer 04","Layer 05")))) -> Layer 03 | R6: =D6/IdealPPO-E6 -> 659.208 | S6: =IdealTP*Weeks-(Weeks*J6+FirstFill) -> 202.7 | T6: =IF(S6>0,(F6-IdealTP*Weeks*E6)/S6,1000000000000) -> 46.962013 | U6: =IF(E6<=0,0,IF(G6<=IdealTP,0,IF(L6<=IdealPPO,0,INT(MIN(T6,R6)+0.000000001)))) -> 46 | V6: =IF(E6<=0,"No current outlets",IF(G6<=IdealTP,"TP already at or below ideal",IF(L6<=IdealPPO,"PPO already at or below ideal",IF(T6<=R6,"Stopped by TP reaching ideal","Stopped by PPO reaching ideal")))) -> Stopped by TP reaching ideal | W6: =F6+U6*(Weeks*J6+FirstFill) -> 122655 | X6: =E6+U6 -> 157 | Y6: =IFERROR(W6/(X6*Weeks),0) -> 15.023885 | Z6: =IFERROR(D6/X6,0) -> 3679.3376 | AA6: =IF(AND(K6>=NationalPCC,L6>IdealPPO),"Q1: High PCC, High PPO",IF(K6>=NationalPCC,"Q2: High PCC, Low PPO",IF(L6>IdealPPO,"Q3: Low PCC, High PPO","Q4: Low PCC, Low PPO"))) -> Q3: Low PCC, High PPO | AB6: =IF(K6>=NationalPCC,IF(L6>IdealPPO,"Phase 1","Phase 2"),"Phase 3") -> Phase 3 | AC6: =IF(AND(G6>IdealTP,L6>IdealPPO),"High TP, High PPO",IF(G6>IdealTP,"High TP, Low PPO",IF(L6>IdealPPO,"Low TP, High PPO","Low TP, Low PPO"))) -> High TP, High PPO | AD6: =INDEX(WaveNumbers,MATCH(C6,WaveNames,0)) -> 1 | AE6: =IF(U6>0,AD6*10000000+VALUE(RIGHT(AB6,1))*1000000+(1000000-U6)+ROW()/1000000,"") -> 13999954 | AF6: =IF(U6>0,COUNTIFS($AE$5:$AE$119,"<"&AE6)+1,"") -> 18 | AG6: =IF(AF6="","No",IF(AF6<=TopN,"Yes","No")) -> Yes | AH6: =INT('District Data'!O6*ConvRate) -> 41 | AI6: =MIN(U6,AH6) -> 41 | AJ6: =IF(U6=0,"No expansion",IF(AH6<U6,"Supply constrained (not enough shops)","Demand constrained (enough shops)")) -> Supply constrained (not enough shops) | AK6: =IF(AG6="Yes",AI6,0) -> 41 | AL6: =IF(AG6="Yes",IF(Budget1>=ShortlistFinal,AK6,AK6/ShortlistFinal*Budget1),0) -> 24.242424 | AM6: =INT(AL6) -> 24 | AN6: =IF(AND(AG6="Yes",Budget1<ShortlistFinal),AL6-AM6,-1) -> 0.24242424 | AO6: =IF(AG6<>"Yes",0,IF(Budget1>=ShortlistFinal,AK6,AM6+IF(COUNTIFS($AN$5:$AN$119,">"&AN6)+COUNTIFS($AN$5:$AN$119,AN6,$AF$5:$AF$119,"<"&AF6)<Budget1-SUM($AM$5:$AM$119),1,0))) -> 24 | AP6: =IF(AG6="Yes",IF(Budget2>=ShortlistFinal,AK6,AK6/ShortlistFinal*Budget2),0) -> 36.363636 | AQ6: =INT(AP6) -> 36 | AR6: =IF(AND(AG6="Yes",Budget2<ShortlistFinal),AP6-AQ6,-1) -> 0.36363636 | AS6: =IF(AG6<>"Yes",0,IF(Budget2>=ShortlistFinal,AK6,AQ6+IF(COUNTIFS($AR$5:$AR$119,">"&AR6)+COUNTIFS($AR$5:$AR$119,AR6,$AF$5:$AF$119,"<"&AF6)<Budget2-SUM($AQ$5:$AQ$119),1,0))) -> 36 | AT6: =AK6*Share2025 -> 14.470588 | AU6: =AK6*Share2026 -> 14.470588 | AV6: =AK6*Share2027 -> 12.058824 | AW6: =INT(AT6) -> 14 | AX6: =INT(AU6) -> 14 | AY6: =INT(AV6) -> 12 | AZ6: =AT6-AW6 -> 0.47058824 | BA6: =AU6-AX6 -> 0.47058824 | BB6: =AV6-AY6 -> 0.058823529 | BC6: =AK6-AW6-AX6-AY6 -> 1 | BD6: =AW6+IF((BA6>AZ6)+(BB6>AZ6)<BC6,1,0) -> 15 | BE6: =AX6+IF((AZ6>BA6)+(BB6>BA6)+(AZ6=BA6)<BC6,1,0) -> 14 | BF6: =AY6+IF((AZ6>BB6)+(BA6>BB6)+(AZ6=BB6)+(BA6=BB6)<BC6,1,0) -> 12
A7: ='District Data'!A7 -> Awaran | B7: ='District Data'!C7 -> Karachi Region | C7: ='District Data'!D7 -> Rest | D7: =ROUND('District Data'!E7*'District Data'!F7,0) -> 54952 | E7: ='District Data'!I7 -> 6 | F7: ='District Data'!L7 -> 3475.4 | G7: =IFERROR(F7/(E7*Weeks),0) -> 11.139103 | H7: =IFERROR('District Data'!N7/('District Data'!M7*Weeks),0) -> 5.7413462 | I7: =IFERROR(SUMIFS('District Data'!$N$5:$N$119,'District Data'!$C$5:$C$119,B7)/(SUMIFS('District Data'!$M$5:$M$119,'District Data'!$C$5:$C$119,B7)*Weeks),0) -> 12.952447 | J7: =IF(TPBasis="NI TP",IF(H7>0,H7,I7),G7) -> 5.7413462 | K7: =IFERROR(F7/D7,0) -> 0.063244286 | L7: =IFERROR(D7/E7,0) -> 9158.6667 | M7: =IFERROR('District Data'!L7/'District Data'!K7-1,0) -> 0.062585991 | N7: =IFERROR(('District Data'!L7/'District Data'!J7)^(1/2)-1,0) -> 0.089864882 | O7: =IFERROR('District Data'!I7/'District Data'!H7-1,0) -> 0.2 | P7: =IF(K7>=PCC_L1,"Layer 01",IF(K7>=PCC_L2,"Layer 02",IF(K7>=PCC_L3,"Layer 03",IF(K7>=PCC_L4,"Layer 04","Layer 05")))) -> Layer 05 | Q7: =IF(L7>=PPO_L1,"Layer 01",IF(L7>=PPO_L2,"Layer 02",IF(L7>=PPO_L3,"Layer 03",IF(L7>=PPO_L4,"Layer 04","Layer 05")))) -> Layer 03 | R7: =D7/IdealPPO-E7 -> 67.269333 | S7: =IdealTP*Weeks-(Weeks*J7+FirstFill) -> 401.45 | T7: =IF(S7>0,(F7-IdealTP*Weeks*E7)/S7,1000000000000) -> -3.0006227 | U7: =IF(E7<=0,0,IF(G7<=IdealTP,0,IF(L7<=IdealPPO,0,INT(MIN(T7,R7)+0.000000001)))) -> 0 | V7: =IF(E7<=0,"No current outlets",IF(G7<=IdealTP,"TP already at or below ideal",IF(L7<=IdealPPO,"PPO already at or below ideal",IF(T7<=R7,"Stopped by TP reaching ideal","Stopped by PPO reaching ideal")))) -> TP already at or below ideal | W7: =F7+U7*(Weeks*J7+FirstFill) -> 3475.4 | X7: =E7+U7 -> 6 | Y7: =IFERROR(W7/(X7*Weeks),0) -> 11.139103 | Z7: =IFERROR(D7/X7,0) -> 9158.6667 | AA7: =IF(AND(K7>=NationalPCC,L7>IdealPPO),"Q1: High PCC, High PPO",IF(K7>=NationalPCC,"Q2: High PCC, Low PPO",IF(L7>IdealPPO,"Q3: Low PCC, High PPO","Q4: Low PCC, Low PPO"))) -> Q3: Low PCC, High PPO | AB7: =IF(K7>=NationalPCC,IF(L7>IdealPPO,"Phase 1","Phase 2"),"Phase 3") -> Phase 3 | AC7: =IF(AND(G7>IdealTP,L7>IdealPPO),"High TP, High PPO",IF(G7>IdealTP,"High TP, Low PPO",IF(L7>IdealPPO,"Low TP, High PPO","Low TP, Low PPO"))) -> Low TP, High PPO | AD7: =INDEX(WaveNumbers,MATCH(C7,WaveNames,0)) -> 4 | AE7: =IF(U7>0,AD7*10000000+VALUE(RIGHT(AB7,1))*1000000+(1000000-U7)+ROW()/1000000,"") | AF7: =IF(U7>0,COUNTIFS($AE$5:$AE$119,"<"&AE7)+1,"") | AG7: =IF(AF7="","No",IF(AF7<=TopN,"Yes","No")) -> No | AH7: =INT('District Data'!O7*ConvRate) -> 4 | AI7: =MIN(U7,AH7) -> 0 | AJ7: =IF(U7=0,"No expansion",IF(AH7<U7,"Supply constrained (not enough shops)","Demand constrained (enough shops)")) -> No expansion | AK7: =IF(AG7="Yes",AI7,0) -> 0 | AL7: =IF(AG7="Yes",IF(Budget1>=ShortlistFinal,AK7,AK7/ShortlistFinal*Budget1),0) -> 0 | AM7: =INT(AL7) -> 0 | AN7: =IF(AND(AG7="Yes",Budget1<ShortlistFinal),AL7-AM7,-1) -> -1 | AO7: =IF(AG7<>"Yes",0,IF(Budget1>=ShortlistFinal,AK7,AM7+IF(COUNTIFS($AN$5:$AN$119,">"&AN7)+COUNTIFS($AN$5:$AN$119,AN7,$AF$5:$AF$119,"<"&AF7)<Budget1-SUM($AM$5:$AM$119),1,0))) -> 0 | AP7: =IF(AG7="Yes",IF(Budget2>=ShortlistFinal,AK7,AK7/ShortlistFinal*Budget2),0) -> 0 | AQ7: =INT(AP7) -> 0 | AR7: =IF(AND(AG7="Yes",Budget2<ShortlistFinal),AP7-AQ7,-1) -> -1 | AS7: =IF(AG7<>"Yes",0,IF(Budget2>=ShortlistFinal,AK7,AQ7+IF(COUNTIFS($AR$5:$AR$119,">"&AR7)+COUNTIFS($AR$5:$AR$119,AR7,$AF$5:$AF$119,"<"&AF7)<Budget2-SUM($AQ$5:$AQ$119),1,0))) -> 0 | AT7: =AK7*Share2025 -> 0 | AU7: =AK7*Share2026 -> 0 | AV7: =AK7*Share2027 -> 0 | AW7: =INT(AT7) -> 0 | AX7: =INT(AU7) -> 0 | AY7: =INT(AV7) -> 0 | AZ7: =AT7-AW7 -> 0 | BA7: =AU7-AX7 -> 0 | BB7: =AV7-AY7 -> 0 | BC7: =AK7-AW7-AX7-AY7 -> 0 | BD7: =AW7+IF((BA7>AZ7)+(BB7>AZ7)<BC7,1,0) -> 0 | BE7: =AX7+IF((AZ7>BA7)+(BB7>BA7)+(AZ7=BA7)<BC7,1,0) -> 0 | BF7: =AY7+IF((AZ7>BB7)+(BA7>BB7)+(AZ7=BB7)+(BA7=BB7)<BC7,1,0) -> 0
A8: ='District Data'!A8 -> Badin | B8: ='District Data'!C8 -> Karachi Region | C8: ='District Data'!D8 -> Neighbouring | D8: =ROUND('District Data'!E8*'District Data'!F8,0) -> 467323 | E8: ='District Data'!I8 -> 110 | F8: ='District Data'!L8 -> 88179.1 | G8: =IFERROR(F8/(E8*Weeks),0) -> 15.415927 | H8: =IFERROR('District Data'!N8/('District Data'!M8*Weeks),0) -> 6.4382867 | I8: =IFERROR(SUMIFS('District Data'!$N$5:$N$119,'District Data'!$C$5:$C$119,B8)/(SUMIFS('District Data'!$M$5:$M$119,'District Data'!$C$5:$C$119,B8)*Weeks),0) -> 12.952447 | J8: =IF(TPBasis="NI TP",IF(H8>0,H8,I8),G8) -> 6.4382867 | K8: =IFERROR(F8/D8,0) -> 0.18868984 | L8: =IFERROR(D8/E8,0) -> 4248.3909 | M8: =IFERROR('District Data'!L8/'District Data'!K8-1,0) -> 0.1109038 | N8: =IFERROR(('District Data'!L8/'District Data'!J8)^(1/2)-1,0) -> 0.079192083 | O8: =IFERROR('District Data'!I8/'District Data'!H8-1,0) -> 0.078431373 | P8: =IF(K8>=PCC_L1,"Layer 01",IF(K8>=PCC_L2,"Layer 02",IF(K8>=PCC_L3,"Layer 03",IF(K8>=PCC_L4,"Layer 04","Layer 05")))) -> Layer 05 | Q8: =IF(L8>=PPO_L1,"Layer 01",IF(L8>=PPO_L2,"Layer 02",IF(L8>=PPO_L3,"Layer 03",IF(L8>=PPO_L4,"Layer 04","Layer 05")))) -> Layer 03 | R8: =D8/IdealPPO-E8 -> 513.09733 | S8: =IdealTP*Weeks-(Weeks*J8+FirstFill) -> 365.20909 | T8: =IF(S8>0,(F8-IdealTP*Weeks*E8)/S8,1000000000000) -> 6.5143504 | U8: =IF(E8<=0,0,IF(G8<=IdealTP,0,IF(L8<=IdealPPO,0,INT(MIN(T8,R8)+0.000000001)))) -> 6 | V8: =IF(E8<=0,"No current outlets",IF(G8<=IdealTP,"TP already at or below ideal",IF(L8<=IdealPPO,"PPO already at or below ideal",IF(T8<=R8,"Stopped by TP reaching ideal","Stopped by PPO reaching ideal")))) -> Stopped by TP reaching ideal | W8: =F8+U8*(Weeks*J8+FirstFill) -> 90667.845 | X8: =E8+U8 -> 116 | Y8: =IFERROR(W8/(X8*Weeks),0) -> 15.031141 | Z8: =IFERROR(D8/X8,0) -> 4028.6466 | AA8: =IF(AND(K8>=NationalPCC,L8>IdealPPO),"Q1: High PCC, High PPO",IF(K8>=NationalPCC,"Q2: High PCC, Low PPO",IF(L8>IdealPPO,"Q3: Low PCC, High PPO","Q4: Low PCC, Low PPO"))) -> Q3: Low PCC, High PPO | AB8: =IF(K8>=NationalPCC,IF(L8>IdealPPO,"Phase 1","Phase 2"),"Phase 3") -> Phase 3 | AC8: =IF(AND(G8>IdealTP,L8>IdealPPO),"High TP, High PPO",IF(G8>IdealTP,"High TP, Low PPO",IF(L8>IdealPPO,"Low TP, High PPO","Low TP, Low PPO"))) -> High TP, High PPO | AD8: =INDEX(WaveNumbers,MATCH(C8,WaveNames,0)) -> 2 | AE8: =IF(U8>0,AD8*10000000+VALUE(RIGHT(AB8,1))*1000000+(1000000-U8)+ROW()/1000000,"") -> 23999994 | AF8: =IF(U8>0,COUNTIFS($AE$5:$AE$119,"<"&AE8)+1,"") -> 34 | AG8: =IF(AF8="","No",IF(AF8<=TopN,"Yes","No")) -> Yes | AH8: =INT('District Data'!O8*ConvRate) -> 49 | AI8: =MIN(U8,AH8) -> 6 | AJ8: =IF(U8=0,"No expansion",IF(AH8<U8,"Supply constrained (not enough shops)","Demand constrained (enough shops)")) -> Demand constrained (enough shops) | AK8: =IF(AG8="Yes",AI8,0) -> 6 | AL8: =IF(AG8="Yes",IF(Budget1>=ShortlistFinal,AK8,AK8/ShortlistFinal*Budget1),0) -> 3.5476718 | AM8: =INT(AL8) -> 3 | AN8: =IF(AND(AG8="Yes",Budget1<ShortlistFinal),AL8-AM8,-1) -> 0.54767184 | AO8: =IF(AG8<>"Yes",0,IF(Budget1>=ShortlistFinal,AK8,AM8+IF(COUNTIFS($AN$5:$AN$119,">"&AN8)+COUNTIFS($AN$5:$AN$119,AN8,$AF$5:$AF$119,"<"&AF8)<Budget1-SUM($AM$5:$AM$119),1,0))) -> 4 | AP8: =IF(AG8="Yes",IF(Budget2>=ShortlistFinal,AK8,AK8/ShortlistFinal*Budget2),0) -> 5.3215078 | AQ8: =INT(AP8) -> 5 | AR8: =IF(AND(AG8="Yes",Budget2<ShortlistFinal),AP8-AQ8,-1) -> 0.32150776 | AS8: =IF(AG8<>"Yes",0,IF(Budget2>=ShortlistFinal,AK8,AQ8+IF(COUNTIFS($AR$5:$AR$119,">"&AR8)+COUNTIFS($AR$5:$AR$119,AR8,$AF$5:$AF$119,"<"&AF8)<Budget2-SUM($AQ$5:$AQ$119),1,0))) -> 5 | AT8: =AK8*Share2025 -> 2.1176471 | AU8: =AK8*Share2026 -> 2.1176471 | AV8: =AK8*Share2027 -> 1.7647059 | AW8: =INT(AT8) -> 2 | AX8: =INT(AU8) -> 2 | AY8: =INT(AV8) -> 1 | AZ8: =AT8-AW8 -> 0.11764706 | BA8: =AU8-AX8 -> 0.11764706 | BB8: =AV8-AY8 -> 0.76470588 | BC8: =AK8-AW8-AX8-AY8 -> 1 | BD8: =AW8+IF((BA8>AZ8)+(BB8>AZ8)<BC8,1,0) -> 2 | BE8: =AX8+IF((AZ8>BA8)+(BB8>BA8)+(AZ8=BA8)<BC8,1,0) -> 2 | BF8: =AY8+IF((AZ8>BB8)+(BA8>BB8)+(AZ8=BB8)+(BA8=BB8)<BC8,1,0) -> 2
A9: ='District Data'!A9 -> Bahawalnagar | B9: ='District Data'!C9 -> Multan Region | C9: ='District Data'!D9 -> Population High | D9: =ROUND('District Data'!E9*'District Data'!F9,0) -> 914098 | E9: ='District Data'!I9 -> 146 | F9: ='District Data'!L9 -> 107197.5 | G9: =IFERROR(F9/(E9*Weeks),0) -> 14.119797 | H9: =IFERROR('District Data'!N9/('District Data'!M9*Weeks),0) -> 8.0125874 | I9: =IFERROR(SUMIFS('District Data'!$N$5:$N$119,'District Data'!$C$5:$C$119,B9)/(SUMIFS('District Data'!$M$5:$M$119,'District Data'!$C$5:$C$119,B9)*Weeks),0) -> 8.1666329 | J9: =IF(TPBasis="NI TP",IF(H9>0,H9,I9),G9) -> 8.0125874 | K9: =IFERROR(F9/D9,0) -> 0.11727134 | L9: =IFERROR(D9/E9,0) -> 6260.9452 | M9: =IFERROR('District Data'!L9/'District Data'!K9-1,0) -> -0.013268716 | N9: =IFERROR(('District Data'!L9/'District Data'!J9)^(1/2)-1,0) -> 0.019056844 | O9: =IFERROR('District Data'!I9/'District Data'!H9-1,0) -> 0.042857143 | P9: =IF(K9>=PCC_L1,"Layer 01",IF(K9>=PCC_L2,"Layer 02",IF(K9>=PCC_L3,"Layer 03",IF(K9>=PCC_L4,"Layer 04","Layer 05")))) -> Layer 05 | Q9: =IF(L9>=PPO_L1,"Layer 01",IF(L9>=PPO_L2,"Layer 02",IF(L9>=PPO_L3,"Layer 03",IF(L9>=PPO_L4,"Layer 04","Layer 05")))) -> Layer 03 | R9: =D9/IdealPPO-E9 -> 1072.7973 | S9: =IdealTP*Weeks-(Weeks*J9+FirstFill) -> 283.34545 | T9: =IF(S9>0,(F9-IdealTP*Weeks*E9)/S9,1000000000000) -> -23.584285 | U9: =IF(E9<=0,0,IF(G9<=IdealTP,0,IF(L9<=IdealPPO,0,INT(MIN(T9,R9)+0.000000001)))) -> 0 | V9: =IF(E9<=0,"No current outlets",IF(G9<=IdealTP,"TP already at or below ideal",IF(L9<=IdealPPO,"PPO already at or below ideal",IF(T9<=R9,"Stopped by TP reaching ideal","Stopped by PPO reaching ideal")))) -> TP already at or below ideal | W9: =F9+U9*(Weeks*J9+FirstFill) -> 107197.5 | X9: =E9+U9 -> 146 | Y9: =IFERROR(W9/(X9*Weeks),0) -> 14.119797 | Z9: =IFERROR(D9/X9,0) -> 6260.9452 | AA9: =IF(AND(K9>=NationalPCC,L9>IdealPPO),"Q1: High PCC, High PPO",IF(K9>=NationalPCC,"Q2: High PCC, Low PPO",IF(L9>IdealPPO,"Q3: Low PCC, High PPO","Q4: Low PCC, Low PPO"))) -> Q3: Low PCC, High PPO | AB9: =IF(K9>=NationalPCC,IF(L9>IdealPPO,"Phase 1","Phase 2"),"Phase 3") -> Phase 3 | AC9: =IF(AND(G9>IdealTP,L9>IdealPPO),"High TP, High PPO",IF(G9>IdealTP,"High TP, Low PPO",IF(L9>IdealPPO,"Low TP, High PPO","Low TP, Low PPO"))) -> Low TP, High PPO | AD9: =INDEX(WaveNumbers,MATCH(C9,WaveNames,0)) -> 3 | AE9: =IF(U9>0,AD9*10000000+VALUE(RIGHT(AB9,1))*1000000+(1000000-U9)+ROW()/1000000,"") | AF9: =IF(U9>0,COUNTIFS($AE$5:$AE$119,"<"&AE9)+1,"") | AG9: =IF(AF9="","No",IF(AF9<=TopN,"Yes","No")) -> No | AH9: =INT('District Data'!O9*ConvRate) -> 47 | AI9: =MIN(U9,AH9) -> 0 | AJ9: =IF(U9=0,"No expansion",IF(AH9<U9,"Supply constrained (not enough shops)","Demand constrained (enough shops)")) -> No expansion | AK9: =IF(AG9="Yes",AI9,0) -> 0 | AL9: =IF(AG9="Yes",IF(Budget1>=ShortlistFinal,AK9,AK9/ShortlistFinal*Budget1),0) -> 0 | AM9: =INT(AL9) -> 0 | AN9: =IF(AND(AG9="Yes",Budget1<ShortlistFinal),AL9-AM9,-1) -> -1 | AO9: =IF(AG9<>"Yes",0,IF(Budget1>=ShortlistFinal,AK9,AM9+IF(COUNTIFS($AN$5:$AN$119,">"&AN9)+COUNTIFS($AN$5:$AN$119,AN9,$AF$5:$AF$119,"<"&AF9)<Budget1-SUM($AM$5:$AM$119),1,0))) -> 0 | AP9: =IF(AG9="Yes",IF(Budget2>=ShortlistFinal,AK9,AK9/ShortlistFinal*Budget2),0) -> 0 | AQ9: =INT(AP9) -> 0 | AR9: =IF(AND(AG9="Yes",Budget2<ShortlistFinal),AP9-AQ9,-1) -> -1 | AS9: =IF(AG9<>"Yes",0,IF(Budget2>=ShortlistFinal,AK9,AQ9+IF(COUNTIFS($AR$5:$AR$119,">"&AR9)+COUNTIFS($AR$5:$AR$119,AR9,$AF$5:$AF$119,"<"&AF9)<Budget2-SUM($AQ$5:$AQ$119),1,0))) -> 0 | AT9: =AK9*Share2025 -> 0 | AU9: =AK9*Share2026 -> 0 | AV9: =AK9*Share2027 -> 0 | AW9: =INT(AT9) -> 0 | AX9: =INT(AU9) -> 0 | AY9: =INT(AV9) -> 0 | AZ9: =AT9-AW9 -> 0 | BA9: =AU9-AX9 -> 0 | BB9: =AV9-AY9 -> 0 | BC9: =AK9-AW9-AX9-AY9 -> 0 | BD9: =AW9+IF((BA9>AZ9)+(BB9>AZ9)<BC9,1,0) -> 0 | BE9: =AX9+IF((AZ9>BA9)+(BB9>BA9)+(AZ9=BA9)<BC9,1,0) -> 0 | BF9: =AY9+IF((AZ9>BB9)+(BA9>BB9)+(AZ9=BB9)+(BA9=BB9)<BC9,1,0) -> 0
A10: ='District Data'!A10 -> Bahawalpur | B10: ='District Data'!C10 -> Multan Region | C10: ='District Data'!D10 -> Neighbouring | D10: =ROUND('District Data'!E10*'District Data'!F10,0) -> 1648945 | E10: ='District Data'!I10 -> 309 | F10: ='District Data'!L10 -> 191928.8 | G10: =IFERROR(F10/(E10*Weeks),0) -> 11.944785 | H10: =IFERROR('District Data'!N10/('District Data'!M10*Weeks),0) -> 6.502967 | I10: =IFERROR(SUMIFS('District Data'!$N$5:$N$119,'District Data'!$C$5:$C$119,B10)/(SUMIFS('District Data'!$M$5:$M$119,'District Data'!$C$5:$C$119,B10)*Weeks),0) -> 8.1666329 | J10: =IF(TPBasis="NI TP",IF(H10>0,H10,I10),G10) -> 6.502967 | K10: =IFERROR(F10/D10,0) -> 0.11639491 | L10: =IFERROR(D10/E10,0) -> 5336.3916 | M10: =IFERROR('District Data'!L10/'District Data'!K10-1,0) -> 0.023928264 | N10: =IFERROR(('District Data'!L10/'District Data'!J10)^(1/2)-1,0) -> 0.018385372 | O10: =IFERROR('District Data'!I10/'District Data'!H10-1,0) -> 0.088028169 | P10: =IF(K10>=PCC_L1,"Layer 01",IF(K10>=PCC_L2,"Layer 02",IF(K10>=PCC_L3,"Layer 03",IF(K10>=PCC_L4,"Layer 04","Layer 05")))) -> Layer 05 | Q10: =IF(L10>=PPO_L1,"Layer 01",IF(L10>=PPO_L2,"Layer 02",IF(L10>=PPO_L3,"Layer 03",IF(L10>=PPO_L4,"Layer 04","Layer 05")))) -> Layer 03 | R10: =D10/IdealPPO-E10 -> 1889.5933 | S10: =IdealTP*Weeks-(Weeks*J10+FirstFill) -> 361.84571 | T10: =IF(S10>0,(F10-IdealTP*Weeks*E10)/S10,1000000000000) -> -135.66887 | U10: =IF(E10<=0,0,IF(G10<=IdealTP,0,IF(L10<=IdealPPO,0,INT(MIN(T10,R10)+0.000000001)))) -> 0 | V10: =IF(E10<=0,"No current outlets",IF(G10<=IdealTP,"TP already at or below ideal",IF(L10<=IdealPPO,"PPO already at or below ideal",IF(T10<=R10,"Stopped by TP reaching ideal","Stopped by PPO reaching ideal")))) -> TP already at or below ideal | W10: =F10+U10*(Weeks*J10+FirstFill) -> 191928.8 | X10: =E10+U10 -> 309 | Y10: =IFERROR(W10/(X10*Weeks),0) -> 11.944785 | Z10: =IFERROR(D10/X10,0) -> 5336.3916 | AA10: =IF(AND(K10>=NationalPCC,L10>IdealPPO),"Q1: High PCC, High PPO",IF(K10>=NationalPCC,"Q2: High PCC, Low PPO",IF(L10>IdealPPO,"Q3: Low PCC, High PPO","Q4: Low PCC, Low PPO"))) -> Q3: Low PCC, High PPO | AB10: =IF(K10>=NationalPCC,IF(L10>IdealPPO,"Phase 1","Phase 2"),"Phase 3") -> Phase 3 | AC10: =IF(AND(G10>IdealTP,L10>IdealPPO),"High TP, High PPO",IF(G10>IdealTP,"High TP, Low PPO",IF(L10>IdealPPO,"Low TP, High PPO","Low TP, Low PPO"))) -> Low TP, High PPO | AD10: =INDEX(WaveNumbers,MATCH(C10,WaveNames,0)) -> 2 | AE10: =IF(U10>0,AD10*10000000+VALUE(RIGHT(AB10,1))*1000000+(1000000-U10)+ROW()/1000000,"") | AF10: =IF(U10>0,COUNTIFS($AE$5:$AE$119,"<"&AE10)+1,"") | AG10: =IF(AF10="","No",IF(AF10<=TopN,"Yes","No")) -> No | AH10: =INT('District Data'!O10*ConvRate) -> 73 | AI10: =MIN(U10,AH10) -> 0 | AJ10: =IF(U10=0,"No expansion",IF(AH10<U10,"Supply constrained (not enough shops)","Demand constrained (enough shops)")) -> No expansion | AK10: =IF(AG10="Yes",AI10,0) -> 0 | AL10: =IF(AG10="Yes",IF(Budget1>=ShortlistFinal,AK10,AK10/ShortlistFinal*Budget1),0) -> 0 | AM10: =INT(AL10) -> 0 | AN10: =IF(AND(AG10="Yes",Budget1<ShortlistFinal),AL10-AM10,-1) -> -1 | AO10: =IF(AG10<>"Yes",0,IF(Budget1>=ShortlistFinal,AK10,AM10+IF(COUNTIFS($AN$5:$AN$119,">"&AN10)+COUNTIFS($AN$5:$AN$119,AN10,$AF$5:$AF$119,"<"&AF10)<Budget1-SUM($AM$5:$AM$119),1,0))) -> 0 | AP10: =IF(AG10="Yes",IF(Budget2>=ShortlistFinal,AK10,AK10/ShortlistFinal*Budget2),0) -> 0 | AQ10: =INT(AP10) -> 0 | AR10: =IF(AND(AG10="Yes",Budget2<ShortlistFinal),AP10-AQ10,-1) -> -1 | AS10: =IF(AG10<>"Yes",0,IF(Budget2>=ShortlistFinal,AK10,AQ10+IF(COUNTIFS($AR$5:$AR$119,">"&AR10)+COUNTIFS($AR$5:$AR$119,AR10,$AF$5:$AF$119,"<"&AF10)<Budget2-SUM($AQ$5:$AQ$119),1,0))) -> 0 | AT10: =AK10*Share2025 -> 0 | AU10: =AK10*Share2026 -> 0 | AV10: =AK10*Share2027 -> 0 | AW10: =INT(AT10) -> 0 | AX10: =INT(AU10) -> 0 | AY10: =INT(AV10) -> 0 | AZ10: =AT10-AW10 -> 0 | BA10: =AU10-AX10 -> 0 | BB10: =AV10-AY10 -> 0 | BC10: =AK10-AW10-AX10-AY10 -> 0 | BD10: =AW10+IF((BA10>AZ10)+(BB10>AZ10)<BC10,1,0) -> 0 | BE10: =AX10+IF((AZ10>BA10)+(BB10>BA10)+(AZ10=BA10)<BC10,1,0) -> 0 | BF10: =AY10+IF((AZ10>BB10)+(BA10>BB10)+(AZ10=BB10)+(BA10=BB10)<BC10,1,0) -> 0
A11: ='District Data'!A11 -> Bajaur | B11: ='District Data'!C11 -> Peshawar Region | C11: ='District Data'!D11 -> Rest | D11: =ROUND('District Data'!E11*'District Data'!F11,0) -> 153594 | E11: ='District Data'!I11 -> 17 | F11: ='District Data'!L11 -> 15684.7 | G11: =IFERROR(F11/(E11*Weeks),0) -> 17.742873 | H11: =IFERROR('District Data'!N11/('District Data'!M11*Weeks),0) -> 19.966154 | I11: =IFERROR(SUMIFS('District Data'!$N$5:$N$119,'District Data'!$C$5:$C$119,B11)/(SUMIFS('District Data'!$M$5:$M$119,'District Data'!$C$5:$C$119,B11)*Weeks),0) -> 7.6039705 | J11: =IF(TPBasis="NI TP",IF(H11>0,H11,I11),G11) -> 19.966154 | K11: =IFERROR(F11/D11,0) -> 0.10211792 | L11: =IFERROR(D11/E11,0) -> 9034.9412 | M11: =IFERROR('District Data'!L11/'District Data'!K11-1,0) -> 0.31737779 | N11: =IFERROR(('District Data'!L11/'District Data'!J11)^(1/2)-1,0) -> 0.18071336 | O11: =IFERROR('District Data'!I11/'District Data'!H11-1,0) -> 0.30769231 | P11: =IF(K11>=PCC_L1,"Layer 01",IF(K11>=PCC_L2,"Layer 02",IF(K11>=PCC_L3,"Layer 03",IF(K11>=PCC_L4,"Layer 04","Layer 05")))) -> Layer 05 | Q11: =IF(L11>=PPO_L1,"Layer 01",IF(L11>=PPO_L2,"Layer 02",IF(L11>=PPO_L3,"Layer 03",IF(L11>=PPO_L4,"Layer 04","Layer 05")))) -> Layer 03 | R11: =D11/IdealPPO-E11 -> 187.792 | S11: =IdealTP*Weeks-(Weeks*J11+FirstFill) -> -338.24 | T11: =IF(S11>0,(F11-IdealTP*Weeks*E11)/S11,1000000000000) -> 1000000000000 | U11: =IF(E11<=0,0,IF(G11<=IdealTP,0,IF(L11<=IdealPPO,0,INT(MIN(T11,R11)+0.000000001)))) -> 187 | V11: =IF(E11<=0,"No current outlets",IF(G11<=IdealTP,"TP already at or below ideal",IF(L11<=IdealPPO,"PPO already at or below ideal",IF(T11<=R11,"Stopped by TP reaching ideal","Stopped by PPO reaching ideal")))) -> Stopped by PPO reaching ideal | W11: =F11+U11*(Weeks*J11+FirstFill) -> 224795.58 | X11: =E11+U11 -> 204 | Y11: =IFERROR(W11/(X11*Weeks),0) -> 21.191137 | Z11: =IFERROR(D11/X11,0) -> 752.91176 | AA11: =IF(AND(K11>=NationalPCC,L11>IdealPPO),"Q1: High PCC, High PPO",IF(K11>=NationalPCC,"Q2: High PCC, Low PPO",IF(L11>IdealPPO,"Q3: Low PCC, High PPO","Q4: Low PCC, Low PPO"))) -> Q3: Low PCC, High PPO | AB11: =IF(K11>=NationalPCC,IF(L11>IdealPPO,"Phase 1","Phase 2"),"Phase 3") -> Phase 3 | AC11: =IF(AND(G11>IdealTP,L11>IdealPPO),"High TP, High PPO",IF(G11>IdealTP,"High TP, Low PPO",IF(L11>IdealPPO,"Low TP, High PPO","Low TP, Low PPO"))) -> High TP, High PPO | AD11: =INDEX(WaveNumbers,MATCH(C11,WaveNames,0)) -> 4 | AE11: =IF(U11>0,AD11*10000000+VALUE(RIGHT(AB11,1))*1000000+(1000000-U11)+ROW()/1000000,"") -> 43999813 | AF11: =IF(U11>0,COUNTIFS($AE$5:$AE$119,"<"&AE11)+1,"") -> 39 | AG11: =IF(AF11="","No",IF(AF11<=TopN,"Yes","No")) -> Yes | AH11: =INT('District Data'!O11*ConvRate) -> 4 | AI11: =MIN(U11,AH11) -> 4 | AJ11: =IF(U11=0,"No expansion",IF(AH11<U11,"Supply constrained (not enough shops)","Demand constrained (enough shops)")) -> Supply constrained (not enough shops) | AK11: =IF(AG11="Yes",AI11,0) -> 4 | AL11: =IF(AG11="Yes",IF(Budget1>=ShortlistFinal,AK11,AK11/ShortlistFinal*Budget1),0) -> 2.3651146 | AM11: =INT(AL11) -> 2 | AN11: =IF(AND(AG11="Yes",Budget1<ShortlistFinal),AL11-AM11,-1) -> 0.36511456 | AO11: =IF(AG11<>"Yes",0,IF(Budget1>=ShortlistFinal,AK11,AM11+IF(COUNTIFS($AN$5:$AN$119,">"&AN11)+COUNTIFS($AN$5:$AN$119,AN11,$AF$5:$AF$119,"<"&AF11)<Budget1-SUM($AM$5:$AM$119),1,0))) -> 2 | AP11: =IF(AG11="Yes",IF(Budget2>=ShortlistFinal,AK11,AK11/ShortlistFinal*Budget2),0) -> 3.5476718 | AQ11: =INT(AP11) -> 3 | AR11: =IF(AND(AG11="Yes",Budget2<ShortlistFinal),AP11-AQ11,-1) -> 0.54767184 | AS11: =IF(AG11<>"Yes",0,IF(Budget2>=ShortlistFinal,AK11,AQ11+IF(COUNTIFS($AR$5:$AR$119,">"&AR11)+COUNTIFS($AR$5:$AR$119,AR11,$AF$5:$AF$119,"<"&AF11)<Budget2-SUM($AQ$5:$AQ$119),1,0))) -> 4 | AT11: =AK11*Share2025 -> 1.4117647 | AU11: =AK11*Share2026 -> 1.4117647 | AV11: =AK11*Share2027 -> 1.1764706 | AW11: =INT(AT11) -> 1 | AX11: =INT(AU11) -> 1 | AY11: =INT(AV11) -> 1 | AZ11: =AT11-AW11 -> 0.41176471 | BA11: =AU11-AX11 -> 0.41176471 | BB11: =AV11-AY11 -> 0.17647059 | BC11: =AK11-AW11-AX11-AY11 -> 1 | BD11: =AW11+IF((BA11>AZ11)+(BB11>AZ11)<BC11,1,0) -> 2 | BE11: =AX11+IF((AZ11>BA11)+(BB11>BA11)+(AZ11=BA11)<BC11,1,0) -> 1 | BF11: =AY11+IF((AZ11>BB11)+(BA11>BB11)+(AZ11=BB11)+(BA11=BB11)<BC11,1,0) -> 1
A12: ='District Data'!A12 -> Bannu | B12: ='District Data'!C12 -> Peshawar Region | C12: ='District Data'!D12 -> Rest | D12: =ROUND('District Data'!E12*'District Data'!F12,0) -> 155031 | E12: ='District Data'!I12 -> 15 | F12: ='District Data'!L12 -> 9416.3 | G12: =IFERROR(F12/(E12*Weeks),0) -> 12.072179 | H12: =IFERROR('District Data'!N12/('District Data'!M12*Weeks),0) -> 5.7 | I12: =IFERROR(SUMIFS('District Data'!$N$5:$N$119,'District Data'!$C$5:$C$119,B12)/(SUMIFS('District Data'!$M$5:$M$119,'District Data'!$C$5:$C$119,B12)*Weeks),0) -> 7.6039705 | J12: =IF(TPBasis="NI TP",IF(H12>0,H12,I12),G12) -> 5.7 | K12: =IFERROR(F12/D12,0) -> 0.060738175 | L12: =IFERROR(D12/E12,0) -> 10335.4 | M12: =IFERROR('District Data'!L12/'District Data'!K12-1,0) -> -0.13797775 | N12: =IFERROR(('District Data'!L12/'District Data'!J12)^(1/2)-1,0) -> -0.049513708 | O12: =IFERROR('District Data'!I12/'District Data'!H12-1,0) -> 0 | P12: =IF(K12>=PCC_L1,"Layer 01",IF(K12>=PCC_L2,"Layer 02",IF(K12>=PCC_L3,"Layer 03",IF(K12>=PCC_L4,"Layer 04","Layer 05")))) -> Layer 05 | Q12: =IF(L12>=PPO_L1,"Layer 01",IF(L12>=PPO_L2,"Layer 02",IF(L12>=PPO_L3,"Layer 03",IF(L12>=PPO_L4,"Layer 04","Layer 05")))) -> Layer 03 | R12: =D12/IdealPPO-E12 -> 191.708 | S12: =IdealTP*Weeks-(Weeks*J12+FirstFill) -> 403.6 | T12: =IF(S12>0,(F12-IdealTP*Weeks*E12)/S12,1000000000000) -> -5.6583251 | U12: =IF(E12<=0,0,IF(G12<=IdealTP,0,IF(L12<=IdealPPO,0,INT(MIN(T12,R12)+0.000000001)))) -> 0 | V12: =IF(E12<=0,"No current outlets",IF(G12<=IdealTP,"TP already at or below ideal",IF(L12<=IdealPPO,"PPO already at or below ideal",IF(T12<=R12,"Stopped by TP reaching ideal","Stopped by PPO reaching ideal")))) -> TP already at or below ideal | W12: =F12+U12*(Weeks*J12+FirstFill) -> 9416.3 | X12: =E12+U12 -> 15 | Y12: =IFERROR(W12/(X12*Weeks),0) -> 12.072179 | Z12: =IFERROR(D12/X12,0) -> 10335.4 | AA12: =IF(AND(K12>=NationalPCC,L12>IdealPPO),"Q1: High PCC, High PPO",IF(K12>=NationalPCC,"Q2: High PCC, Low PPO",IF(L12>IdealPPO,"Q3: Low PCC, High PPO","Q4: Low PCC, Low PPO"))) -> Q3: Low PCC, High PPO | AB12: =IF(K12>=NationalPCC,IF(L12>IdealPPO,"Phase 1","Phase 2"),"Phase 3") -> Phase 3 | AC12: =IF(AND(G12>IdealTP,L12>IdealPPO),"High TP, High PPO",IF(G12>IdealTP,"High TP, Low PPO",IF(L12>IdealPPO,"Low TP, High PPO","Low TP, Low PPO"))) -> Low TP, High PPO | AD12: =INDEX(WaveNumbers,MATCH(C12,WaveNames,0)) -> 4 | AE12: =IF(U12>0,AD12*10000000+VALUE(RIGHT(AB12,1))*1000000+(1000000-U12)+ROW()/1000000,"") | AF12: =IF(U12>0,COUNTIFS($AE$5:$AE$119,"<"&AE12)+1,"") | AG12: =IF(AF12="","No",IF(AF12<=TopN,"Yes","No")) -> No | AH12: =INT('District Data'!O12*ConvRate) -> 10 | AI12: =MIN(U12,AH12) -> 0 | AJ12: =IF(U12=0,"No expansion",IF(AH12<U12,"Supply constrained (not enough shops)","Demand constrained (enough shops)")) -> No expansion | AK12: =IF(AG12="Yes",AI12,0) -> 0 | AL12: =IF(AG12="Yes",IF(Budget1>=ShortlistFinal,AK12,AK12/ShortlistFinal*Budget1),0) -> 0 | AM12: =INT(AL12) -> 0 | AN12: =IF(AND(AG12="Yes",Budget1<ShortlistFinal),AL12-AM12,-1) -> -1 | AO12: =IF(AG12<>"Yes",0,IF(Budget1>=ShortlistFinal,AK12,AM12+IF(COUNTIFS($AN$5:$AN$119,">"&AN12)+COUNTIFS($AN$5:$AN$119,AN12,$AF$5:$AF$119,"<"&AF12)<Budget1-SUM($AM$5:$AM$119),1,0))) -> 0 | AP12: =IF(AG12="Yes",IF(Budget2>=ShortlistFinal,AK12,AK12/ShortlistFinal*Budget2),0) -> 0 | AQ12: =INT(AP12) -> 0 | AR12: =IF(AND(AG12="Yes",Budget2<ShortlistFinal),AP12-AQ12,-1) -> -1 | AS12: =IF(AG12<>"Yes",0,IF(Budget2>=ShortlistFinal,AK12,AQ12+IF(COUNTIFS($AR$5:$AR$119,">"&AR12)+COUNTIFS($AR$5:$AR$119,AR12,$AF$5:$AF$119,"<"&AF12)<Budget2-SUM($AQ$5:$AQ$119),1,0))) -> 0 | AT12: =AK12*Share2025 -> 0 | AU12: =AK12*Share2026 -> 0 | AV12: =AK12*Share2027 -> 0 | AW12: =INT(AT12) -> 0 | AX12: =INT(AU12) -> 0 | AY12: =INT(AV12) -> 0 | AZ12: =AT12-AW12 -> 0 | BA12: =AU12-AX12 -> 0 | BB12: =AV12-AY12 -> 0 | BC12: =AK12-AW12-AX12-AY12 -> 0 | BD12: =AW12+IF((BA12>AZ12)+(BB12>AZ12)<BC12,1,0) -> 0 | BE12: =AX12+IF((AZ12>BA12)+(BB12>BA12)+(AZ12=BA12)<BC12,1,0) -> 0 | BF12: =AY12+IF((AZ12>BB12)+(BA12>BB12)+(AZ12=BB12)+(BA12=BB12)<BC12,1,0) -> 0
A13: ='District Data'!A13 -> Barkhan | B13: ='District Data'!C13 -> Multan Region | C13: ='District Data'!D13 -> Rest | D13: =ROUND('District Data'!E13*'District Data'!F13,0) -> 22196 | E13: ='District Data'!I13 -> 2 | F13: ='District Data'!L13 -> 1300.4 | G13: =IFERROR(F13/(E13*Weeks),0) -> 12.503846 | H13: =IFERROR('District Data'!N13/('District Data'!M13*Weeks),0) -> 0 | I13: =IFERROR(SUMIFS('District Data'!$N$5:$N$119,'District Data'!$C$5:$C$119,B13)/(SUMIFS('District Data'!$M$5:$M$119,'District Data'!$C$5:$C$119,B13)*Weeks),0) -> 8.1666329 | J13: =IF(TPBasis="NI TP",IF(H13>0,H13,I13),G13) -> 8.1666329 | K13: =IFERROR(F13/D13,0) -> 0.058587133 | L13: =IFERROR(D13/E13,0) -> 11098 | M13: =IFERROR('District Data'!L13/'District Data'!K13-1,0) -> -0.040082675 | N13: =IFERROR(('District Data'!L13/'District Data'!J13)^(1/2)-1,0) -> -0.040059762 | O13: =IFERROR('District Data'!I13/'District Data'!H13-1,0) -> 0 | P13: =IF(K13>=PCC_L1,"Layer 01",IF(K13>=PCC_L2,"Layer 02",IF(K13>=PCC_L3,"Layer 03",IF(K13>=PCC_L4,"Layer 04","Layer 05")))) -> Layer 05 | Q13: =IF(L13>=PPO_L1,"Layer 01",IF(L13>=PPO_L2,"Layer 02",IF(L13>=PPO_L3,"Layer 03",IF(L13>=PPO_L4,"Layer 04","Layer 05")))) -> Layer 03 | R13: =D13/IdealPPO-E13 -> 27.594667 | S13: =IdealTP*Weeks-(Weeks*J13+FirstFill) -> 275.33509 | T13: =IF(S13>0,(F13-IdealTP*Weeks*E13)/S13,1000000000000) -> -0.94285112 | U13: =IF(E13<=0,0,IF(G13<=IdealTP,0,IF(L13<=IdealPPO,0,INT(MIN(T13,R13)+0.000000001)))) -> 0 | V13: =IF(E13<=0,"No current outlets",IF(G13<=IdealTP,"TP already at or below ideal",IF(L13<=IdealPPO,"PPO already at or below ideal",IF(T13<=R13,"Stopped by TP reaching ideal","Stopped by PPO reaching ideal")))) -> TP already at or below ideal | W13: =F13+U13*(Weeks*J13+FirstFill) -> 1300.4 | X13: =E13+U13 -> 2 | Y13: =IFERROR(W13/(X13*Weeks),0) -> 12.503846 | Z13: =IFERROR(D13/X13,0) -> 11098 | AA13: =IF(AND(K13>=NationalPCC,L13>IdealPPO),"Q1: High PCC, High PPO",IF(K13>=NationalPCC,"Q2: High PCC, Low PPO",IF(L13>IdealPPO,"Q3: Low PCC, High PPO","Q4: Low PCC, Low PPO"))) -> Q3: Low PCC, High PPO | AB13: =IF(K13>=NationalPCC,IF(L13>IdealPPO,"Phase 1","Phase 2"),"Phase 3") -> Phase 3 | AC13: =IF(AND(G13>IdealTP,L13>IdealPPO),"High TP, High PPO",IF(G13>IdealTP,"High TP, Low PPO",IF(L13>IdealPPO,"Low TP, High PPO","Low TP, Low PPO"))) -> Low TP, High PPO | AD13: =INDEX(WaveNumbers,MATCH(C13,WaveNames,0)) -> 4 | AE13: =IF(U13>0,AD13*10000000+VALUE(RIGHT(AB13,1))*1000000+(1000000-U13)+ROW()/1000000,"") | AF13: =IF(U13>0,COUNTIFS($AE$5:$AE$119,"<"&AE13)+1,"") | AG13: =IF(AF13="","No",IF(AF13<=TopN,"Yes","No")) -> No | AH13: =INT('District Data'!O13*ConvRate) -> 1 | AI13: =MIN(U13,AH13) -> 0 | AJ13: =IF(U13=0,"No expansion",IF(AH13<U13,"Supply constrained (not enough shops)","Demand constrained (enough shops)")) -> No expansion | AK13: =IF(AG13="Yes",AI13,0) -> 0 | AL13: =IF(AG13="Yes",IF(Budget1>=ShortlistFinal,AK13,AK13/ShortlistFinal*Budget1),0) -> 0 | AM13: =INT(AL13) -> 0 | AN13: =IF(AND(AG13="Yes",Budget1<ShortlistFinal),AL13-AM13,-1) -> -1 | AO13: =IF(AG13<>"Yes",0,IF(Budget1>=ShortlistFinal,AK13,AM13+IF(COUNTIFS($AN$5:$AN$119,">"&AN13)+COUNTIFS($AN$5:$AN$119,AN13,$AF$5:$AF$119,"<"&AF13)<Budget1-SUM($AM$5:$AM$119),1,0))) -> 0 | AP13: =IF(AG13="Yes",IF(Budget2>=ShortlistFinal,AK13,AK13/ShortlistFinal*Budget2),0) -> 0 | AQ13: =INT(AP13) -> 0 | AR13: =IF(AND(AG13="Yes",Budget2<ShortlistFinal),AP13-AQ13,-1) -> -1 | AS13: =IF(AG13<>"Yes",0,IF(Budget2>=ShortlistFinal,AK13,AQ13+IF(COUNTIFS($AR$5:$AR$119,">"&AR13)+COUNTIFS($AR$5:$AR$119,AR13,$AF$5:$AF$119,"<"&AF13)<Budget2-SUM($AQ$5:$AQ$119),1,0))) -> 0 | AT13: =AK13*Share2025 -> 0 | AU13: =AK13*Share2026 -> 0 | AV13: =AK13*Share2027 -> 0 | AW13: =INT(AT13) -> 0 | AX13: =INT(AU13) -> 0 | AY13: =INT(AV13) -> 0 | AZ13: =AT13-AW13 -> 0 | BA13: =AU13-AX13 -> 0 | BB13: =AV13-AY13 -> 0 | BC13: =AK13-AW13-AX13-AY13 -> 0 | BD13: =AW13+IF((BA13>AZ13)+(BB13>AZ13)<BC13,1,0) -> 0 | BE13: =AX13+IF((AZ13>BA13)+(BB13>BA13)+(AZ13=BA13)<BC13,1,0) -> 0 | BF13: =AY13+IF((AZ13>BB13)+(BA13>BB13)+(AZ13=BB13)+(BA13=BB13)<BC13,1,0) -> 0
A14: ='District Data'!A14 -> Battagram | B14: ='District Data'!C14 -> Islamabad Region | C14: ='District Data'!D14 -> Rest | D14: =ROUND('District Data'!E14*'District Data'!F14,0) -> 78980 | E14: ='District Data'!I14 -> 11 | F14: ='District Data'!L14 -> 6229.2 | G14: =IFERROR(F14/(E14*Weeks),0) -> 10.89021 | H14: =IFERROR('District Data'!N14/('District Data'!M14*Weeks),0) -> 4.6105769 | I14: =IFERROR(SUMIFS('District Data'!$N$5:$N$119,'District Data'!$C$5:$C$119,B14)/(SUMIFS('District Data'!$M$5:$M$119,'District Data'!$C$5:$C$119,B14)*Weeks),0) -> 8.4031158 | J14: =IF(TPBasis="NI TP",IF(H14>0,H14,I14),G14) -> 4.6105769 | K14: =IFERROR(F14/D14,0) -> 0.0788706 | L14: =IFERROR(D14/E14,0) -> 7180 | M14: =IFERROR('District Data'!L14/'District Data'!K14-1,0) -> 0.1028451 | N14: =IFERROR(('District Data'!L14/'District Data'!J14)^(1/2)-1,0) -> 0.051169763 | O14: =IFERROR('District Data'!I14/'District Data'!H14-1,0) -> 0.22222222 | P14: =IF(K14>=PCC_L1,"Layer 01",IF(K14>=PCC_L2,"Layer 02",IF(K14>=PCC_L3,"Layer 03",IF(K14>=PCC_L4,"Layer 04","Layer 05")))) -> Layer 05 | Q14: =IF(L14>=PPO_L1,"Layer 01",IF(L14>=PPO_L2,"Layer 02",IF(L14>=PPO_L3,"Layer 03",IF(L14>=PPO_L4,"Layer 04","Layer 05")))) -> Layer 03 | R14: =D14/IdealPPO-E14 -> 94.306667 | S14: =IdealTP*Weeks-(Weeks*J14+FirstFill) -> 460.25 | T14: =IF(S14>0,(F14-IdealTP*Weeks*E14)/S14,1000000000000) -> -5.1076589 | U14: =IF(E14<=0,0,IF(G14<=IdealTP,0,IF(L14<=IdealPPO,0,INT(MIN(T14,R14)+0.000000001)))) -> 0 | V14: =IF(E14<=0,"No current outlets",IF(G14<=IdealTP,"TP already at or below ideal",IF(L14<=IdealPPO,"PPO already at or below ideal",IF(T14<=R14,"Stopped by TP reaching ideal","Stopped by PPO reaching ideal")))) -> TP already at or below ideal | W14: =F14+U14*(Weeks*J14+FirstFill) -> 6229.2 | X14: =E14+U14 -> 11 | Y14: =IFERROR(W14/(X14*Weeks),0) -> 10.89021 | Z14: =IFERROR(D14/X14,0) -> 7180 | AA14: =IF(AND(K14>=NationalPCC,L14>IdealPPO),"Q1: High PCC, High PPO",IF(K14>=NationalPCC,"Q2: High PCC, Low PPO",IF(L14>IdealPPO,"Q3: Low PCC, High PPO","Q4: Low PCC, Low PPO"))) -> Q3: Low PCC, High PPO | AB14: =IF(K14>=NationalPCC,IF(L14>IdealPPO,"Phase 1","Phase 2"),"Phase 3") -> Phase 3 | AC14: =IF(AND(G14>IdealTP,L14>IdealPPO),"High TP, High PPO",IF(G14>IdealTP,"High TP, Low PPO",IF(L14>IdealPPO,"Low TP, High PPO","Low TP, Low PPO"))) -> Low TP, High PPO | AD14: =INDEX(WaveNumbers,MATCH(C14,WaveNames,0)) -> 4 | AE14: =IF(U14>0,AD14*10000000+VALUE(RIGHT(AB14,1))*1000000+(1000000-U14)+ROW()/1000000,"") | AF14: =IF(U14>0,COUNTIFS($AE$5:$AE$119,"<"&AE14)+1,"") | AG14: =IF(AF14="","No",IF(AF14<=TopN,"Yes","No")) -> No | AH14: =INT('District Data'!O14*ConvRate) -> 2 | AI14: =MIN(U14,AH14) -> 0 | AJ14: =IF(U14=0,"No expansion",IF(AH14<U14,"Supply constrained (not enough shops)","Demand constrained (enough shops)")) -> No expansion | AK14: =IF(AG14="Yes",AI14,0) -> 0 | AL14: =IF(AG14="Yes",IF(Budget1>=ShortlistFinal,AK14,AK14/ShortlistFinal*Budget1),0) -> 0 | AM14: =INT(AL14) -> 0 | AN14: =IF(AND(AG14="Yes",Budget1<ShortlistFinal),AL14-AM14,-1) -> -1 | AO14: =IF(AG14<>"Yes",0,IF(Budget1>=ShortlistFinal,AK14,AM14+IF(COUNTIFS($AN$5:$AN$119,">"&AN14)+COUNTIFS($AN$5:$AN$119,AN14,$AF$5:$AF$119,"<"&AF14)<Budget1-SUM($AM$5:$AM$119),1,0))) -> 0 | AP14: =IF(AG14="Yes",IF(Budget2>=ShortlistFinal,AK14,AK14/ShortlistFinal*Budget2),0) -> 0 | AQ14: =INT(AP14) -> 0 | AR14: =IF(AND(AG14="Yes",Budget2<ShortlistFinal),AP14-AQ14,-1) -> -1 | AS14: =IF(AG14<>"Yes",0,IF(Budget2>=ShortlistFinal,AK14,AQ14+IF(COUNTIFS($AR$5:$AR$119,">"&AR14)+COUNTIFS($AR$5:$AR$119,AR14,$AF$5:$AF$119,"<"&AF14)<Budget2-SUM($AQ$5:$AQ$119),1,0))) -> 0 | AT14: =AK14*Share2025 -> 0 | AU14: =AK14*Share2026 -> 0 | AV14: =AK14*Share2027 -> 0 | AW14: =INT(AT14) -> 0 | AX14: =INT(AU14) -> 0 | AY14: =INT(AV14) -> 0 | AZ14: =AT14-AW14 -> 0 | BA14: =AU14-AX14 -> 0 | BB14: =AV14-AY14 -> 0 | BC14: =AK14-AW14-AX14-AY14 -> 0 | BD14: =AW14+IF((BA14>AZ14)+(BB14>AZ14)<BC14,1,0) -> 0 | BE14: =AX14+IF((AZ14>BA14)+(BB14>BA14)+(AZ14=BA14)<BC14,1,0) -> 0 | BF14: =AY14+IF((AZ14>BB14)+(BA14>BB14)+(AZ14=BB14)+(BA14=BB14)<BC14,1,0) -> 0
A15: ='District Data'!A15 -> Bhakkar | B15: ='District Data'!C15 -> Multan Region | C15: ='District Data'!D15 -> Neighbouring | D15: =ROUND('District Data'!E15*'District Data'!F15,0) -> 423035 | E15: ='District Data'!I15 -> 38 | F15: ='District Data'!L15 -> 33995.5 | G15: =IFERROR(F15/(E15*Weeks),0) -> 17.2042 | H15: =IFERROR('District Data'!N15/('District Data'!M15*Weeks),0) -> 15.099519 | I15: =IFERROR(SUMIFS('District Data'!$N$5:$N$119,'District Data'!$C$5:$C$119,B15)/(SUMIFS('District Data'!$M$5:$M$119,'District Data'!$C$5:$C$119,B15)*Weeks),0) -> 8.1666329 | J15: =IF(TPBasis="NI TP",IF(H15>0,H15,I15),G15) -> 15.099519 | K15: =IFERROR(F15/D15,0) -> 0.080360963 | L15: =IFERROR(D15/E15,0) -> 11132.5 | M15: =IFERROR('District Data'!L15/'District Data'!K15-1,0) -> 0.027442388 | N15: =IFERROR(('District Data'!L15/'District Data'!J15)^(1/2)-1,0) -> 0.057881071 | O15: =IFERROR('District Data'!I15/'District Data'!H15-1,0) -> 0.027027027 | P15: =IF(K15>=PCC_L1,"Layer 01",IF(K15>=PCC_L2,"Layer 02",IF(K15>=PCC_L3,"Layer 03",IF(K15>=PCC_L4,"Layer 04","Layer 05")))) -> Layer 05 | Q15: =IF(L15>=PPO_L1,"Layer 01",IF(L15>=PPO_L2,"Layer 02",IF(L15>=PPO_L3,"Layer 03",IF(L15>=PPO_L4,"Layer 04","Layer 05")))) -> Layer 03 | R15: =D15/IdealPPO-E15 -> 526.04667 | S15: =IdealTP*Weeks-(Weeks*J15+FirstFill) -> -85.175 | T15: =IF(S15>0,(F15-IdealTP*Weeks*E15)/S15,1000000000000) -> 1000000000000 | U15: =IF(E15<=0,0,IF(G15<=IdealTP,0,IF(L15<=IdealPPO,0,INT(MIN(T15,R15)+0.000000001)))) -> 526 | V15: =IF(E15<=0,"No current outlets",IF(G15<=IdealTP,"TP already at or below ideal",IF(L15<=IdealPPO,"PPO already at or below ideal",IF(T15<=R15,"Stopped by TP reaching ideal","Stopped by PPO reaching ideal")))) -> Stopped by PPO reaching ideal | W15: =F15+U15*(Weeks*J15+FirstFill) -> 489077.55 | X15: =E15+U15 -> 564 | Y15: =IFERROR(W15/(X15*Weeks),0) -> 16.67613 | Z15: =IFERROR(D15/X15,0) -> 750.06206 | AA15: =IF(AND(K15>=NationalPCC,L15>IdealPPO),"Q1: High PCC, High PPO",IF(K15>=NationalPCC,"Q2: High PCC, Low PPO",IF(L15>IdealPPO,"Q3: Low PCC, High PPO","Q4: Low PCC, Low PPO"))) -> Q3: Low PCC, High PPO | AB15: =IF(K15>=NationalPCC,IF(L15>IdealPPO,"Phase 1","Phase 2"),"Phase 3") -> Phase 3 | AC15: =IF(AND(G15>IdealTP,L15>IdealPPO),"High TP, High PPO",IF(G15>IdealTP,"High TP, Low PPO",IF(L15>IdealPPO,"Low TP, High PPO","Low TP, Low PPO"))) -> High TP, High PPO | AD15: =INDEX(WaveNumbers,MATCH(C15,WaveNames,0)) -> 2 | AE15: =IF(U15>0,AD15*10000000+VALUE(RIGHT(AB15,1))*1000000+(1000000-U15)+ROW()/1000000,"") -> 23999474 | AF15: =IF(U15>0,COUNTIFS($AE$5:$AE$119,"<"&AE15)+1,"") -> 23 | AG15: =IF(AF15="","No",IF(AF15<=TopN,"Yes","No")) -> Yes | AH15: =INT('District Data'!O15*ConvRate) -> 52 | AI15: =MIN(U15,AH15) -> 52 | AJ15: =IF(U15=0,"No expansion",IF(AH15<U15,"Supply constrained (not enough shops)","Demand constrained (enough shops)")) -> Supply constrained (not enough shops) | AK15: =IF(AG15="Yes",AI15,0) -> 52 | AL15: =IF(AG15="Yes",IF(Budget1>=ShortlistFinal,AK15,AK15/ShortlistFinal*Budget1),0) -> 30.746489 | AM15: =INT(AL15) -> 30 | AN15: =IF(AND(AG15="Yes",Budget1<ShortlistFinal),AL15-AM15,-1) -> 0.74648928 | AO15: =IF(AG15<>"Yes",0,IF(Budget1>=ShortlistFinal,AK15,AM15+IF(COUNTIFS($AN$5:$AN$119,">"&AN15)+COUNTIFS($AN$5:$AN$119,AN15,$AF$5:$AF$119,"<"&AF15)<Budget1-SUM($AM$5:$AM$119),1,0))) -> 31 | AP15: =IF(AG15="Yes",IF(Budget2>=ShortlistFinal,AK15,AK15/ShortlistFinal*Budget2),0) -> 46.119734 | AQ15: =INT(AP15) -> 46 | AR15: =IF(AND(AG15="Yes",Budget2<ShortlistFinal),AP15-AQ15,-1) -> 0.11973392 | AS15: =IF(AG15<>"Yes",0,IF(Budget2>=ShortlistFinal,AK15,AQ15+IF(COUNTIFS($AR$5:$AR$119,">"&AR15)+COUNTIFS($AR$5:$AR$119,AR15,$AF$5:$AF$119,"<"&AF15)<Budget2-SUM($AQ$5:$AQ$119),1,0))) -> 46 | AT15: =AK15*Share2025 -> 18.352941 | AU15: =AK15*Share2026 -> 18.352941 | AV15: =AK15*Share2027 -> 15.294118 | AW15: =INT(AT15) -> 18 | AX15: =INT(AU15) -> 18 | AY15: =INT(AV15) -> 15 | AZ15: =AT15-AW15 -> 0.35294118 | BA15: =AU15-AX15 -> 0.35294118 | BB15: =AV15-AY15 -> 0.29411765 | BC15: =AK15-AW15-AX15-AY15 -> 1 | BD15: =AW15+IF((BA15>AZ15)+(BB15>AZ15)<BC15,1,0) -> 19 | BE15: =AX15+IF((AZ15>BA15)+(BB15>BA15)+(AZ15=BA15)<BC15,1,0) -> 18 | BF15: =AY15+IF((AZ15>BB15)+(BA15>BB15)+(AZ15=BB15)+(BA15=BB15)<BC15,1,0) -> 15
A16: ='District Data'!A16 -> Buner | B16: ='District Data'!C16 -> Peshawar Region | C16: ='District Data'!D16 -> Neighbouring | D16: =ROUND('District Data'!E16*'District Data'!F16,0) -> 83092 | E16: ='District Data'!I16 -> 7 | F16: ='District Data'!L16 -> 4501.2 | G16: =IFERROR(F16/(E16*Weeks),0) -> 12.365934 | H16: =IFERROR('District Data'!N16/('District Data'!M16*Weeks),0) -> 0 | I16: =IFERROR(SUMIFS('District Data'!$N$5:$N$119,'District Data'!$C$5:$C$119,B16)/(SUMIFS('District Data'!$M$5:$M$119,'District Data'!$C$5:$C$119,B16)*Weeks),0) -> 7.6039705 | J16: =IF(TPBasis="NI TP",IF(H16>0,H16,I16),G16) -> 7.6039705 | K16: =IFERROR(F16/D16,0) -> 0.05417128 | L16: =IFERROR(D16/E16,0) -> 11870.286 | M16: =IFERROR('District Data'!L16/'District Data'!K16-1,0) -> -0.0028577125 | N16: =IFERROR(('District Data'!L16/'District Data'!J16)^(1/2)-1,0) -> -0.065164398 | O16: =IFERROR('District Data'!I16/'District Data'!H16-1,0) -> 0 | P16: =IF(K16>=PCC_L1,"Layer 01",IF(K16>=PCC_L2,"Layer 02",IF(K16>=PCC_L3,"Layer 03",IF(K16>=PCC_L4,"Layer 04","Layer 05")))) -> Layer 05 | Q16: =IF(L16>=PPO_L1,"Layer 01",IF(L16>=PPO_L2,"Layer 02",IF(L16>=PPO_L3,"Layer 03",IF(L16>=PPO_L4,"Layer 04","Layer 05")))) -> Layer 03 | R16: =D16/IdealPPO-E16 -> 103.78933 | S16: =IdealTP*Weeks-(Weeks*J16+FirstFill) -> 304.59353 | T16: =IF(S16>0,(F16-IdealTP*Weeks*E16)/S16,1000000000000) -> -3.1478016 | U16: =IF(E16<=0,0,IF(G16<=IdealTP,0,IF(L16<=IdealPPO,0,INT(MIN(T16,R16)+0.000000001)))) -> 0 | V16: =IF(E16<=0,"No current outlets",IF(G16<=IdealTP,"TP already at or below ideal",IF(L16<=IdealPPO,"PPO already at or below ideal",IF(T16<=R16,"Stopped by TP reaching ideal","Stopped by PPO reaching ideal")))) -> TP already at or below ideal | W16: =F16+U16*(Weeks*J16+FirstFill) -> 4501.2 | X16: =E16+U16 -> 7 | Y16: =IFERROR(W16/(X16*Weeks),0) -> 12.365934 | Z16: =IFERROR(D16/X16,0) -> 11870.286 | AA16: =IF(AND(K16>=NationalPCC,L16>IdealPPO),"Q1: High PCC, High PPO",IF(K16>=NationalPCC,"Q2: High PCC, Low PPO",IF(L16>IdealPPO,"Q3: Low PCC, High PPO","Q4: Low PCC, Low PPO"))) -> Q3: Low PCC, High PPO | AB16: =IF(K16>=NationalPCC,IF(L16>IdealPPO,"Phase 1","Phase 2"),"Phase 3") -> Phase 3 | AC16: =IF(AND(G16>IdealTP,L16>IdealPPO),"High TP, High PPO",IF(G16>IdealTP,"High TP, Low PPO",IF(L16>IdealPPO,"Low TP, High PPO","Low TP, Low PPO"))) -> Low TP, High PPO | AD16: =INDEX(WaveNumbers,MATCH(C16,WaveNames,0)) -> 2 | AE16: =IF(U16>0,AD16*10000000+VALUE(RIGHT(AB16,1))*1000000+(1000000-U16)+ROW()/1000000,"") | AF16: =IF(U16>0,COUNTIFS($AE$5:$AE$119,"<"&AE16)+1,"") | AG16: =IF(AF16="","No",IF(AF16<=TopN,"Yes","No")) -> No | AH16: =INT('District Data'!O16*ConvRate) -> 4 | AI16: =MIN(U16,AH16) -> 0 | AJ16: =IF(U16=0,"No expansion",IF(AH16<U16,"Supply constrained (not enough shops)","Demand constrained (enough shops)")) -> No expansion | AK16: =IF(AG16="Yes",AI16,0) -> 0 | AL16: =IF(AG16="Yes",IF(Budget1>=ShortlistFinal,AK16,AK16/ShortlistFinal*Budget1),0) -> 0 | AM16: =INT(AL16) -> 0 | AN16: =IF(AND(AG16="Yes",Budget1<ShortlistFinal),AL16-AM16,-1) -> -1 | AO16: =IF(AG16<>"Yes",0,IF(Budget1>=ShortlistFinal,AK16,AM16+IF(COUNTIFS($AN$5:$AN$119,">"&AN16)+COUNTIFS($AN$5:$AN$119,AN16,$AF$5:$AF$119,"<"&AF16)<Budget1-SUM($AM$5:$AM$119),1,0))) -> 0 | AP16: =IF(AG16="Yes",IF(Budget2>=ShortlistFinal,AK16,AK16/ShortlistFinal*Budget2),0) -> 0 | AQ16: =INT(AP16) -> 0 | AR16: =IF(AND(AG16="Yes",Budget2<ShortlistFinal),AP16-AQ16,-1) -> -1 | AS16: =IF(AG16<>"Yes",0,IF(Budget2>=ShortlistFinal,AK16,AQ16+IF(COUNTIFS($AR$5:$AR$119,">"&AR16)+COUNTIFS($AR$5:$AR$119,AR16,$AF$5:$AF$119,"<"&AF16)<Budget2-SUM($AQ$5:$AQ$119),1,0))) -> 0 | AT16: =AK16*Share2025 -> 0 | AU16: =AK16*Share2026 -> 0 | AV16: =AK16*Share2027 -> 0 | AW16: =INT(AT16) -> 0 | AX16: =INT(AU16) -> 0 | AY16: =INT(AV16) -> 0 | AZ16: =AT16-AW16 -> 0 | BA16: =AU16-AX16 -> 0 | BB16: =AV16-AY16 -> 0 | BC16: =AK16-AW16-AX16-AY16 -> 0 | BD16: =AW16+IF((BA16>AZ16)+(BB16>AZ16)<BC16,1,0) -> 0 | BE16: =AX16+IF((AZ16>BA16)+(BB16>BA16)+(AZ16=BA16)<BC16,1,0) -> 0 | BF16: =AY16+IF((AZ16>BB16)+(BA16>BB16)+(AZ16=BB16)+(BA16=BB16)<BC16,1,0) -> 0
